{
 "cells": [
  {
   "cell_type": "markdown",
   "metadata": {},
   "source": [
    "### Load Images"
   ]
  },
  {
   "cell_type": "code",
   "execution_count": 2,
   "metadata": {},
   "outputs": [
    {
     "name": "stdout",
     "output_type": "stream",
     "text": [
      "2.0.0\n"
     ]
    }
   ],
   "source": [
    "# TensorFlow and tf.keras\n",
    "import tensorflow as tf\n",
    "import tensorflow as tf\n",
    "from tensorflow.keras.preprocessing.image import ImageDataGenerator\n",
    "\n",
    "# Helper libraries\n",
    "import numpy as np\n",
    "import matplotlib.pyplot as plt\n",
    "\n",
    "print(tf.__version__)\n"
   ]
  },
  {
   "cell_type": "markdown",
   "metadata": {},
   "source": [
    "#### Constant Variables"
   ]
  },
  {
   "cell_type": "code",
   "execution_count": 1,
   "metadata": {},
   "outputs": [],
   "source": [
    "# Pfad zum Hauptordner, der die Unterordner mit Bildern enthält\n",
    "main_folder = 'path_to_main_folder'\n",
    "\n",
    "# Auflösung der Bilder in das Format für das neuronale Netz\n",
    "desired_height = 256\n",
    "desired_width = 256\n",
    "\n",
    "# Anzahl der zu klassifizierenden Schilder inklusive \"kein Schild\"\n",
    "number_of_classes = 8"
   ]
  },
  {
   "cell_type": "markdown",
   "metadata": {},
   "source": [
    "#### Data Augmentation Pipeline"
   ]
  },
  {
   "cell_type": "code",
   "execution_count": 3,
   "metadata": {},
   "outputs": [],
   "source": [
    "# Erstellen eines ImageDataGenerator für Data Augmentation\n",
    "train_datagen = ImageDataGenerator(\n",
    "    rescale=1./255,   # Normalisieren der Bilder\n",
    "    rotation_range=40,  # Zufällige Rotation der Bilder\n",
    "    width_shift_range=0.2,  # Horizontaler Shift\n",
    "    height_shift_range=0.2, # Vertikaler Shift\n",
    "    shear_range=0.2,        # Scherung\n",
    "    zoom_range=0.2,         # Zoom\n",
    "    horizontal_flip=True,   # Horizontales Flippen\n",
    "    fill_mode='nearest'     # Füllmethode für neue Pixel\n",
    ")"
   ]
  },
  {
   "cell_type": "markdown",
   "metadata": {},
   "source": [
    "#### Load images with tf.flow_from_directory() to directly create corresponding labels "
   ]
  },
  {
   "cell_type": "code",
   "execution_count": 4,
   "metadata": {},
   "outputs": [
    {
     "name": "stderr",
     "output_type": "stream",
     "text": [
      "ERROR:root:Internal Python error in the inspect module.\n",
      "Below is the traceback from this internal error.\n",
      "\n",
      "ERROR:root:Internal Python error in the inspect module.\n",
      "Below is the traceback from this internal error.\n",
      "\n",
      "ERROR:root:Internal Python error in the inspect module.\n",
      "Below is the traceback from this internal error.\n",
      "\n"
     ]
    },
    {
     "name": "stdout",
     "output_type": "stream",
     "text": [
      "Traceback (most recent call last):\n",
      "  File \"c:\\Users\\aaron\\anaconda3\\envs\\deep_learning\\lib\\site-packages\\IPython\\core\\interactiveshell.py\", line 3457, in run_code\n",
      "    exec(code_obj, self.user_global_ns, self.user_ns)\n",
      "  File \"C:\\Users\\aaron\\AppData\\Local\\Temp\\ipykernel_13336\\2889319893.py\", line 9, in <module>\n",
      "    class_mode='categorical'  # Für mehrklassige Klassifizierung\n",
      "  File \"c:\\Users\\aaron\\anaconda3\\envs\\deep_learning\\lib\\site-packages\\keras_preprocessing\\image\\image_data_generator.py\", line 543, in flow_from_directory\n",
      "    dtype=self.dtype\n",
      "  File \"c:\\Users\\aaron\\anaconda3\\envs\\deep_learning\\lib\\site-packages\\keras_preprocessing\\image\\directory_iterator.py\", line 115, in __init__\n",
      "    for subdir in sorted(os.listdir(directory)):\n",
      "FileNotFoundError: [WinError 3] The system cannot find the path specified: 'path_to_main_folder'\n",
      "\n",
      "During handling of the above exception, another exception occurred:\n",
      "\n",
      "Traceback (most recent call last):\n",
      "  File \"c:\\Users\\aaron\\anaconda3\\envs\\deep_learning\\lib\\site-packages\\IPython\\core\\interactiveshell.py\", line 2077, in showtraceback\n",
      "    stb = value._render_traceback_()\n",
      "AttributeError: 'FileNotFoundError' object has no attribute '_render_traceback_'\n",
      "\n",
      "During handling of the above exception, another exception occurred:\n",
      "\n",
      "Traceback (most recent call last):\n",
      "  File \"c:\\Users\\aaron\\anaconda3\\envs\\deep_learning\\lib\\site-packages\\IPython\\core\\ultratb.py\", line 1101, in get_records\n",
      "    return _fixed_getinnerframes(etb, number_of_lines_of_context, tb_offset)\n",
      "  File \"c:\\Users\\aaron\\anaconda3\\envs\\deep_learning\\lib\\site-packages\\IPython\\core\\ultratb.py\", line 248, in wrapped\n",
      "    return f(*args, **kwargs)\n",
      "  File \"c:\\Users\\aaron\\anaconda3\\envs\\deep_learning\\lib\\site-packages\\IPython\\core\\ultratb.py\", line 281, in _fixed_getinnerframes\n",
      "    records = fix_frame_records_filenames(inspect.getinnerframes(etb, context))\n",
      "  File \"c:\\Users\\aaron\\anaconda3\\envs\\deep_learning\\lib\\inspect.py\", line 1502, in getinnerframes\n",
      "    frameinfo = (tb.tb_frame,) + getframeinfo(tb, context)\n",
      "  File \"c:\\Users\\aaron\\anaconda3\\envs\\deep_learning\\lib\\inspect.py\", line 1460, in getframeinfo\n",
      "    filename = getsourcefile(frame) or getfile(frame)\n",
      "  File \"c:\\Users\\aaron\\anaconda3\\envs\\deep_learning\\lib\\inspect.py\", line 696, in getsourcefile\n",
      "    if getattr(getmodule(object, filename), '__loader__', None) is not None:\n",
      "  File \"c:\\Users\\aaron\\anaconda3\\envs\\deep_learning\\lib\\inspect.py\", line 733, in getmodule\n",
      "    if ismodule(module) and hasattr(module, '__file__'):\n",
      "  File \"c:\\Users\\aaron\\anaconda3\\envs\\deep_learning\\lib\\site-packages\\tensorflow\\__init__.py\", line 50, in __getattr__\n",
      "    module = self._load()\n",
      "  File \"c:\\Users\\aaron\\anaconda3\\envs\\deep_learning\\lib\\site-packages\\tensorflow\\__init__.py\", line 44, in _load\n",
      "    module = _importlib.import_module(self.__name__)\n",
      "  File \"c:\\Users\\aaron\\anaconda3\\envs\\deep_learning\\lib\\importlib\\__init__.py\", line 127, in import_module\n",
      "    return _bootstrap._gcd_import(name[level:], package, level)\n",
      "  File \"<frozen importlib._bootstrap>\", line 1006, in _gcd_import\n",
      "  File \"<frozen importlib._bootstrap>\", line 983, in _find_and_load\n",
      "  File \"<frozen importlib._bootstrap>\", line 965, in _find_and_load_unlocked\n",
      "ModuleNotFoundError: No module named 'tensorflow_core.estimator'\n",
      "Traceback (most recent call last):\n",
      "  File \"c:\\Users\\aaron\\anaconda3\\envs\\deep_learning\\lib\\site-packages\\IPython\\core\\interactiveshell.py\", line 3457, in run_code\n",
      "    exec(code_obj, self.user_global_ns, self.user_ns)\n",
      "  File \"C:\\Users\\aaron\\AppData\\Local\\Temp\\ipykernel_13336\\2889319893.py\", line 9, in <module>\n",
      "    class_mode='categorical'  # Für mehrklassige Klassifizierung\n",
      "  File \"c:\\Users\\aaron\\anaconda3\\envs\\deep_learning\\lib\\site-packages\\keras_preprocessing\\image\\image_data_generator.py\", line 543, in flow_from_directory\n",
      "    dtype=self.dtype\n",
      "  File \"c:\\Users\\aaron\\anaconda3\\envs\\deep_learning\\lib\\site-packages\\keras_preprocessing\\image\\directory_iterator.py\", line 115, in __init__\n",
      "    for subdir in sorted(os.listdir(directory)):\n",
      "FileNotFoundError: [WinError 3] The system cannot find the path specified: 'path_to_main_folder'\n",
      "\n",
      "During handling of the above exception, another exception occurred:\n",
      "\n",
      "Traceback (most recent call last):\n",
      "  File \"c:\\Users\\aaron\\anaconda3\\envs\\deep_learning\\lib\\site-packages\\IPython\\core\\interactiveshell.py\", line 2077, in showtraceback\n",
      "    stb = value._render_traceback_()\n",
      "AttributeError: 'FileNotFoundError' object has no attribute '_render_traceback_'\n",
      "\n",
      "During handling of the above exception, another exception occurred:\n",
      "\n",
      "Traceback (most recent call last):\n",
      "  File \"c:\\Users\\aaron\\anaconda3\\envs\\deep_learning\\lib\\site-packages\\IPython\\core\\interactiveshell.py\", line 3377, in run_ast_nodes\n",
      "    if (await self.run_code(code, result,  async_=asy)):\n",
      "  File \"c:\\Users\\aaron\\anaconda3\\envs\\deep_learning\\lib\\site-packages\\IPython\\core\\interactiveshell.py\", line 3474, in run_code\n",
      "    self.showtraceback(running_compiled_code=True)\n",
      "  File \"c:\\Users\\aaron\\anaconda3\\envs\\deep_learning\\lib\\site-packages\\IPython\\core\\interactiveshell.py\", line 2080, in showtraceback\n",
      "    value, tb, tb_offset=tb_offset)\n",
      "  File \"c:\\Users\\aaron\\anaconda3\\envs\\deep_learning\\lib\\site-packages\\IPython\\core\\ultratb.py\", line 1368, in structured_traceback\n",
      "    self, etype, value, tb, tb_offset, number_of_lines_of_context)\n",
      "  File \"c:\\Users\\aaron\\anaconda3\\envs\\deep_learning\\lib\\site-packages\\IPython\\core\\ultratb.py\", line 1268, in structured_traceback\n",
      "    self, etype, value, tb, tb_offset, number_of_lines_of_context\n",
      "  File \"c:\\Users\\aaron\\anaconda3\\envs\\deep_learning\\lib\\site-packages\\IPython\\core\\ultratb.py\", line 1125, in structured_traceback\n",
      "    tb_offset)\n",
      "  File \"c:\\Users\\aaron\\anaconda3\\envs\\deep_learning\\lib\\site-packages\\IPython\\core\\ultratb.py\", line 1082, in format_exception_as_a_whole\n",
      "    last_unique, recursion_repeat = find_recursion(orig_etype, evalue, records)\n",
      "  File \"c:\\Users\\aaron\\anaconda3\\envs\\deep_learning\\lib\\site-packages\\IPython\\core\\ultratb.py\", line 382, in find_recursion\n",
      "    return len(records), 0\n",
      "TypeError: object of type 'NoneType' has no len()\n",
      "\n",
      "During handling of the above exception, another exception occurred:\n",
      "\n",
      "Traceback (most recent call last):\n",
      "  File \"c:\\Users\\aaron\\anaconda3\\envs\\deep_learning\\lib\\site-packages\\IPython\\core\\interactiveshell.py\", line 2077, in showtraceback\n",
      "    stb = value._render_traceback_()\n",
      "AttributeError: 'TypeError' object has no attribute '_render_traceback_'\n",
      "\n",
      "During handling of the above exception, another exception occurred:\n",
      "\n",
      "Traceback (most recent call last):\n",
      "  File \"c:\\Users\\aaron\\anaconda3\\envs\\deep_learning\\lib\\site-packages\\IPython\\core\\ultratb.py\", line 1101, in get_records\n",
      "    return _fixed_getinnerframes(etb, number_of_lines_of_context, tb_offset)\n",
      "  File \"c:\\Users\\aaron\\anaconda3\\envs\\deep_learning\\lib\\site-packages\\IPython\\core\\ultratb.py\", line 248, in wrapped\n",
      "    return f(*args, **kwargs)\n",
      "  File \"c:\\Users\\aaron\\anaconda3\\envs\\deep_learning\\lib\\site-packages\\IPython\\core\\ultratb.py\", line 281, in _fixed_getinnerframes\n",
      "    records = fix_frame_records_filenames(inspect.getinnerframes(etb, context))\n",
      "  File \"c:\\Users\\aaron\\anaconda3\\envs\\deep_learning\\lib\\inspect.py\", line 1502, in getinnerframes\n",
      "    frameinfo = (tb.tb_frame,) + getframeinfo(tb, context)\n",
      "  File \"c:\\Users\\aaron\\anaconda3\\envs\\deep_learning\\lib\\inspect.py\", line 1460, in getframeinfo\n",
      "    filename = getsourcefile(frame) or getfile(frame)\n",
      "  File \"c:\\Users\\aaron\\anaconda3\\envs\\deep_learning\\lib\\inspect.py\", line 696, in getsourcefile\n",
      "    if getattr(getmodule(object, filename), '__loader__', None) is not None:\n",
      "  File \"c:\\Users\\aaron\\anaconda3\\envs\\deep_learning\\lib\\inspect.py\", line 733, in getmodule\n",
      "    if ismodule(module) and hasattr(module, '__file__'):\n",
      "  File \"c:\\Users\\aaron\\anaconda3\\envs\\deep_learning\\lib\\site-packages\\tensorflow\\__init__.py\", line 50, in __getattr__\n",
      "    module = self._load()\n",
      "  File \"c:\\Users\\aaron\\anaconda3\\envs\\deep_learning\\lib\\site-packages\\tensorflow\\__init__.py\", line 44, in _load\n",
      "    module = _importlib.import_module(self.__name__)\n",
      "  File \"c:\\Users\\aaron\\anaconda3\\envs\\deep_learning\\lib\\importlib\\__init__.py\", line 127, in import_module\n",
      "    return _bootstrap._gcd_import(name[level:], package, level)\n",
      "  File \"<frozen importlib._bootstrap>\", line 1006, in _gcd_import\n",
      "  File \"<frozen importlib._bootstrap>\", line 983, in _find_and_load\n",
      "  File \"<frozen importlib._bootstrap>\", line 965, in _find_and_load_unlocked\n",
      "ModuleNotFoundError: No module named 'tensorflow_core.estimator'\n",
      "Traceback (most recent call last):\n",
      "  File \"c:\\Users\\aaron\\anaconda3\\envs\\deep_learning\\lib\\site-packages\\IPython\\core\\interactiveshell.py\", line 3457, in run_code\n",
      "    exec(code_obj, self.user_global_ns, self.user_ns)\n",
      "  File \"C:\\Users\\aaron\\AppData\\Local\\Temp\\ipykernel_13336\\2889319893.py\", line 9, in <module>\n",
      "    class_mode='categorical'  # Für mehrklassige Klassifizierung\n",
      "  File \"c:\\Users\\aaron\\anaconda3\\envs\\deep_learning\\lib\\site-packages\\keras_preprocessing\\image\\image_data_generator.py\", line 543, in flow_from_directory\n",
      "    dtype=self.dtype\n",
      "  File \"c:\\Users\\aaron\\anaconda3\\envs\\deep_learning\\lib\\site-packages\\keras_preprocessing\\image\\directory_iterator.py\", line 115, in __init__\n",
      "    for subdir in sorted(os.listdir(directory)):\n",
      "FileNotFoundError: [WinError 3] The system cannot find the path specified: 'path_to_main_folder'\n",
      "\n",
      "During handling of the above exception, another exception occurred:\n",
      "\n",
      "Traceback (most recent call last):\n",
      "  File \"c:\\Users\\aaron\\anaconda3\\envs\\deep_learning\\lib\\site-packages\\IPython\\core\\interactiveshell.py\", line 2077, in showtraceback\n",
      "    stb = value._render_traceback_()\n",
      "AttributeError: 'FileNotFoundError' object has no attribute '_render_traceback_'\n",
      "\n",
      "During handling of the above exception, another exception occurred:\n",
      "\n",
      "Traceback (most recent call last):\n",
      "  File \"c:\\Users\\aaron\\anaconda3\\envs\\deep_learning\\lib\\site-packages\\IPython\\core\\interactiveshell.py\", line 3377, in run_ast_nodes\n",
      "    if (await self.run_code(code, result,  async_=asy)):\n",
      "  File \"c:\\Users\\aaron\\anaconda3\\envs\\deep_learning\\lib\\site-packages\\IPython\\core\\interactiveshell.py\", line 3474, in run_code\n",
      "    self.showtraceback(running_compiled_code=True)\n",
      "  File \"c:\\Users\\aaron\\anaconda3\\envs\\deep_learning\\lib\\site-packages\\IPython\\core\\interactiveshell.py\", line 2080, in showtraceback\n",
      "    value, tb, tb_offset=tb_offset)\n",
      "  File \"c:\\Users\\aaron\\anaconda3\\envs\\deep_learning\\lib\\site-packages\\IPython\\core\\ultratb.py\", line 1368, in structured_traceback\n",
      "    self, etype, value, tb, tb_offset, number_of_lines_of_context)\n",
      "  File \"c:\\Users\\aaron\\anaconda3\\envs\\deep_learning\\lib\\site-packages\\IPython\\core\\ultratb.py\", line 1268, in structured_traceback\n",
      "    self, etype, value, tb, tb_offset, number_of_lines_of_context\n",
      "  File \"c:\\Users\\aaron\\anaconda3\\envs\\deep_learning\\lib\\site-packages\\IPython\\core\\ultratb.py\", line 1125, in structured_traceback\n",
      "    tb_offset)\n",
      "  File \"c:\\Users\\aaron\\anaconda3\\envs\\deep_learning\\lib\\site-packages\\IPython\\core\\ultratb.py\", line 1082, in format_exception_as_a_whole\n",
      "    last_unique, recursion_repeat = find_recursion(orig_etype, evalue, records)\n",
      "  File \"c:\\Users\\aaron\\anaconda3\\envs\\deep_learning\\lib\\site-packages\\IPython\\core\\ultratb.py\", line 382, in find_recursion\n",
      "    return len(records), 0\n",
      "TypeError: object of type 'NoneType' has no len()\n",
      "\n",
      "During handling of the above exception, another exception occurred:\n",
      "\n",
      "Traceback (most recent call last):\n",
      "  File \"c:\\Users\\aaron\\anaconda3\\envs\\deep_learning\\lib\\site-packages\\IPython\\core\\interactiveshell.py\", line 2077, in showtraceback\n",
      "    stb = value._render_traceback_()\n",
      "AttributeError: 'TypeError' object has no attribute '_render_traceback_'\n",
      "\n",
      "During handling of the above exception, another exception occurred:\n",
      "\n",
      "Traceback (most recent call last):\n",
      "  File \"c:\\Users\\aaron\\anaconda3\\envs\\deep_learning\\lib\\site-packages\\IPython\\core\\interactiveshell.py\", line 2960, in _run_cell\n",
      "    return runner(coro)\n",
      "  File \"c:\\Users\\aaron\\anaconda3\\envs\\deep_learning\\lib\\site-packages\\IPython\\core\\async_helpers.py\", line 78, in _pseudo_sync_runner\n",
      "    coro.send(None)\n",
      "  File \"c:\\Users\\aaron\\anaconda3\\envs\\deep_learning\\lib\\site-packages\\IPython\\core\\interactiveshell.py\", line 3186, in run_cell_async\n",
      "    interactivity=interactivity, compiler=compiler, result=result)\n",
      "  File \"c:\\Users\\aaron\\anaconda3\\envs\\deep_learning\\lib\\site-packages\\IPython\\core\\interactiveshell.py\", line 3396, in run_ast_nodes\n",
      "    self.showtraceback()\n",
      "  File \"c:\\Users\\aaron\\anaconda3\\envs\\deep_learning\\lib\\site-packages\\IPython\\core\\interactiveshell.py\", line 2080, in showtraceback\n",
      "    value, tb, tb_offset=tb_offset)\n",
      "  File \"c:\\Users\\aaron\\anaconda3\\envs\\deep_learning\\lib\\site-packages\\IPython\\core\\ultratb.py\", line 1368, in structured_traceback\n",
      "    self, etype, value, tb, tb_offset, number_of_lines_of_context)\n",
      "  File \"c:\\Users\\aaron\\anaconda3\\envs\\deep_learning\\lib\\site-packages\\IPython\\core\\ultratb.py\", line 1268, in structured_traceback\n",
      "    self, etype, value, tb, tb_offset, number_of_lines_of_context\n",
      "  File \"c:\\Users\\aaron\\anaconda3\\envs\\deep_learning\\lib\\site-packages\\IPython\\core\\ultratb.py\", line 1143, in structured_traceback\n",
      "    chained_exceptions_tb_offset)\n",
      "  File \"c:\\Users\\aaron\\anaconda3\\envs\\deep_learning\\lib\\site-packages\\IPython\\core\\ultratb.py\", line 1082, in format_exception_as_a_whole\n",
      "    last_unique, recursion_repeat = find_recursion(orig_etype, evalue, records)\n",
      "  File \"c:\\Users\\aaron\\anaconda3\\envs\\deep_learning\\lib\\site-packages\\IPython\\core\\ultratb.py\", line 382, in find_recursion\n",
      "    return len(records), 0\n",
      "TypeError: object of type 'NoneType' has no len()\n",
      "\n",
      "During handling of the above exception, another exception occurred:\n",
      "\n",
      "Traceback (most recent call last):\n",
      "  File \"c:\\Users\\aaron\\anaconda3\\envs\\deep_learning\\lib\\site-packages\\IPython\\core\\interactiveshell.py\", line 2077, in showtraceback\n",
      "    stb = value._render_traceback_()\n",
      "AttributeError: 'TypeError' object has no attribute '_render_traceback_'\n",
      "\n",
      "During handling of the above exception, another exception occurred:\n",
      "\n",
      "Traceback (most recent call last):\n",
      "  File \"c:\\Users\\aaron\\anaconda3\\envs\\deep_learning\\lib\\site-packages\\IPython\\core\\ultratb.py\", line 1101, in get_records\n",
      "    return _fixed_getinnerframes(etb, number_of_lines_of_context, tb_offset)\n",
      "  File \"c:\\Users\\aaron\\anaconda3\\envs\\deep_learning\\lib\\site-packages\\IPython\\core\\ultratb.py\", line 248, in wrapped\n",
      "    return f(*args, **kwargs)\n",
      "  File \"c:\\Users\\aaron\\anaconda3\\envs\\deep_learning\\lib\\site-packages\\IPython\\core\\ultratb.py\", line 281, in _fixed_getinnerframes\n",
      "    records = fix_frame_records_filenames(inspect.getinnerframes(etb, context))\n",
      "  File \"c:\\Users\\aaron\\anaconda3\\envs\\deep_learning\\lib\\inspect.py\", line 1502, in getinnerframes\n",
      "    frameinfo = (tb.tb_frame,) + getframeinfo(tb, context)\n",
      "  File \"c:\\Users\\aaron\\anaconda3\\envs\\deep_learning\\lib\\inspect.py\", line 1460, in getframeinfo\n",
      "    filename = getsourcefile(frame) or getfile(frame)\n",
      "  File \"c:\\Users\\aaron\\anaconda3\\envs\\deep_learning\\lib\\inspect.py\", line 696, in getsourcefile\n",
      "    if getattr(getmodule(object, filename), '__loader__', None) is not None:\n",
      "  File \"c:\\Users\\aaron\\anaconda3\\envs\\deep_learning\\lib\\inspect.py\", line 733, in getmodule\n",
      "    if ismodule(module) and hasattr(module, '__file__'):\n",
      "  File \"c:\\Users\\aaron\\anaconda3\\envs\\deep_learning\\lib\\site-packages\\tensorflow\\__init__.py\", line 50, in __getattr__\n",
      "    module = self._load()\n",
      "  File \"c:\\Users\\aaron\\anaconda3\\envs\\deep_learning\\lib\\site-packages\\tensorflow\\__init__.py\", line 44, in _load\n",
      "    module = _importlib.import_module(self.__name__)\n",
      "  File \"c:\\Users\\aaron\\anaconda3\\envs\\deep_learning\\lib\\importlib\\__init__.py\", line 127, in import_module\n",
      "    return _bootstrap._gcd_import(name[level:], package, level)\n",
      "  File \"<frozen importlib._bootstrap>\", line 1006, in _gcd_import\n",
      "  File \"<frozen importlib._bootstrap>\", line 983, in _find_and_load\n",
      "  File \"<frozen importlib._bootstrap>\", line 965, in _find_and_load_unlocked\n",
      "ModuleNotFoundError: No module named 'tensorflow_core.estimator'\n"
     ]
    }
   ],
   "source": [
    "# Laden der Bilder und Labels aus den Unterordnern\n",
    "train_generator = train_datagen.flow_from_directory(\n",
    "    main_folder,\n",
    "    target_size=(desired_height, desired_width),  # Zielgröße der Bilder\n",
    "    batch_size=32,\n",
    "    class_mode='categorical'  # Für mehrklassige Klassifizierung\n",
    ")"
   ]
  },
  {
   "cell_type": "markdown",
   "metadata": {},
   "source": [
    "#### Create own model"
   ]
  },
  {
   "cell_type": "code",
   "execution_count": null,
   "metadata": {},
   "outputs": [],
   "source": [
    "# Erstellen des Modells (hier ein einfaches Beispiel)\n",
    "model = tf.keras.models.Sequential([\n",
    "    tf.keras.layers.Conv2D(32, (3, 3), activation='relu', input_shape=(desired_height, desired_width, 3)),\n",
    "    tf.keras.layers.MaxPooling2D(2, 2),\n",
    "    # Weitere Schichten nach Bedarf hinzufügen\n",
    "    tf.keras.layers.Flatten(),\n",
    "    tf.keras.layers.Dense(512, activation='relu'),\n",
    "    tf.keras.layers.Dense(number_of_classes, activation='softmax')  # Anzahl der Klassen\n",
    "])"
   ]
  },
  {
   "cell_type": "markdown",
   "metadata": {},
   "source": [
    "#### Compile and train model"
   ]
  },
  {
   "cell_type": "code",
   "execution_count": null,
   "metadata": {},
   "outputs": [],
   "source": [
    "# Kompilieren des Modells\n",
    "model.compile(optimizer='adam', loss='categorical_crossentropy', metrics=['accuracy'])\n",
    "\n",
    "# Training des Modells\n",
    "history = model.fit(\n",
    "    train_generator,\n",
    "    steps_per_epoch=100,\n",
    "    epochs=15,\n",
    "    # Weitere Parameter nach Bedarf\n",
    ")"
   ]
  }
 ],
 "metadata": {
  "kernelspec": {
   "display_name": "deep_learning",
   "language": "python",
   "name": "python3"
  },
  "language_info": {
   "codemirror_mode": {
    "name": "ipython",
    "version": 3
   },
   "file_extension": ".py",
   "mimetype": "text/x-python",
   "name": "python",
   "nbconvert_exporter": "python",
   "pygments_lexer": "ipython3",
   "version": "3.7.16"
  }
 },
 "nbformat": 4,
 "nbformat_minor": 2
}
